Traceback (most recent call last):
  File "C:\Users\tripats\.conda\envs\rpo-project\Lib\site-packages\wandb\sdk\wandb_config.py", line 162, in __getattr__
    return self.__getitem__(key)
           ^^^^^^^^^^^^^^^^^^^^^
  File "C:\Users\tripats\.conda\envs\rpo-project\Lib\site-packages\wandb\sdk\wandb_config.py", line 130, in __getitem__
    return self._items[key]
           ~~~~~~~~~~~^^^^^
KeyError: 'lr'
The above exception was the direct cause of the following exception:
Traceback (most recent call last):
  File "C:\Users\tripats\Documents\GitHub\rpo_ppo_contrast\rpo_continuous_action.py", line 420, in <module>
    main()
  File "C:\Users\tripats\Documents\GitHub\rpo_ppo_contrast\rpo_continuous_action.py", line 202, in main
    args.learning_rate = wandb.config.lr
                         ^^^^^^^^^^^^^^^
  File "C:\Users\tripats\.conda\envs\rpo-project\Lib\site-packages\wandb\sdk\wandb_config.py", line 164, in __getattr__
    raise AttributeError(
AttributeError: <class 'wandb.sdk.wandb_config.Config'> object has no attribute 'lr'